2021-06-25 12:58:04,582 INFO: Microblog startup [in C:\Users\Arina\python_git\Platform_for_sport\microblog\app\__init__.py:45]
2021-06-25 13:16:33,780 INFO: Microblog startup [in C:\Users\Arina\python_git\Platform_for_sport\microblog\app\__init__.py:45]
2021-06-25 13:16:54,130 INFO: Microblog startup [in C:\Users\Arina\python_git\Platform_for_sport\microblog\app\__init__.py:45]
2021-06-25 13:32:45,381 INFO: Microblog startup [in C:\Users\Arina\python_git\Platform_for_sport\microblog\app\__init__.py:45]
2021-06-25 13:42:06,400 INFO: Microblog startup [in C:\Users\Arina\python_git\Platform_for_sport\microblog\app\__init__.py:45]
2021-06-25 13:55:10,763 INFO: Microblog startup [in C:\Users\Arina\python_git\Platform_for_sport\microblog\app\__init__.py:45]
2021-06-25 13:58:50,520 INFO: Microblog startup [in C:\Users\Arina\python_git\Platform_for_sport\microblog\app\__init__.py:45]
2021-06-25 14:06:57,216 INFO: Microblog startup [in C:\Users\Arina\python_git\Platform_for_sport\microblog\app\__init__.py:45]
2021-06-25 14:54:46,480 INFO: Microblog startup [in C:\Users\Arina\python_git\Platform_for_sport\microblog\app\__init__.py:45]
2021-06-25 14:56:36,673 INFO: Microblog startup [in C:\Users\Arina\python_git\Platform_for_sport\microblog\app\__init__.py:45]
2021-06-25 14:58:13,553 INFO: Microblog startup [in C:\Users\Arina\python_git\Platform_for_sport\microblog\app\__init__.py:45]
2021-06-25 15:06:55,192 INFO: Microblog startup [in C:\Users\Arina\python_git\Platform_for_sport\microblog\app\__init__.py:45]
2021-06-25 15:24:06,491 INFO: Microblog startup [in C:\Users\Arina\python_git\Platform_for_sport\microblog\app\__init__.py:45]
2021-06-25 15:24:17,485 ERROR: Exception on /user/Arina [GET] [in C:\Users\Arina\Anaconda3\lib\site-packages\flask\app.py:1761]
Traceback (most recent call last):
  File "C:\Users\Arina\Anaconda3\lib\site-packages\sqlalchemy\engine\base.py", line 1244, in _execute_context
    cursor, statement, parameters, context
  File "C:\Users\Arina\Anaconda3\lib\site-packages\sqlalchemy\engine\default.py", line 552, in do_execute
    cursor.execute(statement, parameters)
sqlite3.OperationalError: no such column: followers.followed_id

The above exception was the direct cause of the following exception:

Traceback (most recent call last):
  File "C:\Users\Arina\Anaconda3\lib\site-packages\flask\app.py", line 2292, in wsgi_app
    response = self.full_dispatch_request()
  File "C:\Users\Arina\Anaconda3\lib\site-packages\flask\app.py", line 1815, in full_dispatch_request
    rv = self.handle_user_exception(e)
  File "C:\Users\Arina\Anaconda3\lib\site-packages\flask\app.py", line 1718, in handle_user_exception
    reraise(exc_type, exc_value, tb)
  File "C:\Users\Arina\Anaconda3\lib\site-packages\flask\_compat.py", line 35, in reraise
    raise value
  File "C:\Users\Arina\Anaconda3\lib\site-packages\flask\app.py", line 1813, in full_dispatch_request
    rv = self.dispatch_request()
  File "C:\Users\Arina\Anaconda3\lib\site-packages\flask\app.py", line 1799, in dispatch_request
    return self.view_functions[rule.endpoint](**req.view_args)
  File "C:\Users\Arina\Anaconda3\lib\site-packages\flask_login\utils.py", line 272, in decorated_view
    return func(*args, **kwargs)
  File "C:\Users\Arina\python_git\Platform_for_sport\microblog\app\routes.py", line 71, in profile
    return render_template('profile.html', user = user, events = events, form = form)
  File "C:\Users\Arina\Anaconda3\lib\site-packages\flask\templating.py", line 135, in render_template
    context, ctx.app)
  File "C:\Users\Arina\Anaconda3\lib\site-packages\flask\templating.py", line 117, in _render
    rv = template.render(context)
  File "C:\Users\Arina\Anaconda3\lib\site-packages\jinja2\asyncsupport.py", line 76, in render
    return original_render(self, *args, **kwargs)
  File "C:\Users\Arina\Anaconda3\lib\site-packages\jinja2\environment.py", line 1008, in render
    return self.environment.handle_exception(exc_info, True)
  File "C:\Users\Arina\Anaconda3\lib\site-packages\jinja2\environment.py", line 780, in handle_exception
    reraise(exc_type, exc_value, tb)
  File "C:\Users\Arina\Anaconda3\lib\site-packages\jinja2\_compat.py", line 37, in reraise
    raise value.with_traceback(tb)
  File "C:\Users\Arina\python_git\Platform_for_sport\microblog\app\templates\profile.html", line 1, in top-level template code
    {% extends "base.html" %}
  File "C:\Users\Arina\python_git\Platform_for_sport\microblog\app\templates\base.html", line 29, in top-level template code
    {% block content %}{% endblock %}
  File "C:\Users\Arina\python_git\Platform_for_sport\microblog\app\templates\profile.html", line 11, in block "content"
    <p>{{ user.followers.count() }} followers, {{ user.followed.count() }} following.</p>
  File "C:\Users\Arina\Anaconda3\lib\site-packages\sqlalchemy\orm\dynamic.py", line 323, in count
    return self._clone(sess).count()
  File "C:\Users\Arina\Anaconda3\lib\site-packages\sqlalchemy\orm\query.py", line 3561, in count
    return self.from_self(col).scalar()
  File "C:\Users\Arina\Anaconda3\lib\site-packages\sqlalchemy\orm\query.py", line 3305, in scalar
    ret = self.one()
  File "C:\Users\Arina\Anaconda3\lib\site-packages\sqlalchemy\orm\query.py", line 3275, in one
    ret = self.one_or_none()
  File "C:\Users\Arina\Anaconda3\lib\site-packages\sqlalchemy\orm\query.py", line 3244, in one_or_none
    ret = list(self)
  File "C:\Users\Arina\Anaconda3\lib\site-packages\sqlalchemy\orm\query.py", line 3317, in __iter__
    return self._execute_and_instances(context)
  File "C:\Users\Arina\Anaconda3\lib\site-packages\sqlalchemy\orm\query.py", line 3342, in _execute_and_instances
    result = conn.execute(querycontext.statement, self._params)
  File "C:\Users\Arina\Anaconda3\lib\site-packages\sqlalchemy\engine\base.py", line 988, in execute
    return meth(self, multiparams, params)
  File "C:\Users\Arina\Anaconda3\lib\site-packages\sqlalchemy\sql\elements.py", line 287, in _execute_on_connection
    return connection._execute_clauseelement(self, multiparams, params)
  File "C:\Users\Arina\Anaconda3\lib\site-packages\sqlalchemy\engine\base.py", line 1107, in _execute_clauseelement
    distilled_params,
  File "C:\Users\Arina\Anaconda3\lib\site-packages\sqlalchemy\engine\base.py", line 1248, in _execute_context
    e, statement, parameters, cursor, context
  File "C:\Users\Arina\Anaconda3\lib\site-packages\sqlalchemy\engine\base.py", line 1466, in _handle_dbapi_exception
    util.raise_from_cause(sqlalchemy_exception, exc_info)
  File "C:\Users\Arina\Anaconda3\lib\site-packages\sqlalchemy\util\compat.py", line 383, in raise_from_cause
    reraise(type(exception), exception, tb=exc_tb, cause=cause)
  File "C:\Users\Arina\Anaconda3\lib\site-packages\sqlalchemy\util\compat.py", line 128, in reraise
    raise value.with_traceback(tb)
  File "C:\Users\Arina\Anaconda3\lib\site-packages\sqlalchemy\engine\base.py", line 1244, in _execute_context
    cursor, statement, parameters, context
  File "C:\Users\Arina\Anaconda3\lib\site-packages\sqlalchemy\engine\default.py", line 552, in do_execute
    cursor.execute(statement, parameters)
sqlalchemy.exc.OperationalError: (sqlite3.OperationalError) no such column: followers.followed_id
[SQL: SELECT count(*) AS count_1 
FROM (SELECT user.id AS user_id, user.username AS user_username, user.email AS user_email, user.password_hash AS user_password_hash, user.about_me AS user_about_me, user.last_seen AS user_last_seen 
FROM user, followers 
WHERE followers.followed_id = ? AND followers.follower_id = user.id) AS anon_1]
[parameters: (2,)]
(Background on this error at: http://sqlalche.me/e/e3q8)
2021-06-25 17:21:47,198 INFO: Microblog startup [in C:\Users\Arina\python_git\Platform_for_sport\microblog\app\__init__.py:45]
2021-06-25 17:22:30,463 INFO: Microblog startup [in C:\Users\Arina\python_git\Platform_for_sport\microblog\app\__init__.py:45]
2021-06-25 17:24:21,710 INFO: Microblog startup [in C:\Users\Arina\python_git\Platform_for_sport\microblog\app\__init__.py:45]
2021-06-25 17:25:21,403 INFO: Microblog startup [in C:\Users\Arina\python_git\Platform_for_sport\microblog\app\__init__.py:45]
2021-06-25 18:04:36,234 INFO: Microblog startup [in C:\Users\Arina\python_git\Platform_for_sport\microblog\app\__init__.py:45]
