2021-06-26 11:50:19,201 ERROR: Exception on /user/Arina [GET] [in C:\Users\Arina\Anaconda3\lib\site-packages\flask\app.py:1761]
Traceback (most recent call last):
  File "C:\Users\Arina\Anaconda3\lib\site-packages\flask\app.py", line 2292, in wsgi_app
    response = self.full_dispatch_request()
  File "C:\Users\Arina\Anaconda3\lib\site-packages\flask\app.py", line 1815, in full_dispatch_request
    rv = self.handle_user_exception(e)
  File "C:\Users\Arina\Anaconda3\lib\site-packages\flask\app.py", line 1718, in handle_user_exception
    reraise(exc_type, exc_value, tb)
  File "C:\Users\Arina\Anaconda3\lib\site-packages\flask\_compat.py", line 35, in reraise
    raise value
  File "C:\Users\Arina\Anaconda3\lib\site-packages\flask\app.py", line 1813, in full_dispatch_request
    rv = self.dispatch_request()
  File "C:\Users\Arina\Anaconda3\lib\site-packages\flask\app.py", line 1799, in dispatch_request
    return self.view_functions[rule.endpoint](**req.view_args)
  File "C:\Users\Arina\Anaconda3\lib\site-packages\flask_login\utils.py", line 272, in decorated_view
    return func(*args, **kwargs)
  File "C:\Users\Arina\python_git\Platform_for_sport\microblog\app\routes.py", line 75, in profile
    return render_template('profile.html', user = user, events = events, form = form)
  File "C:\Users\Arina\Anaconda3\lib\site-packages\flask\templating.py", line 135, in render_template
    context, ctx.app)
  File "C:\Users\Arina\Anaconda3\lib\site-packages\flask\templating.py", line 117, in _render
    rv = template.render(context)
  File "C:\Users\Arina\Anaconda3\lib\site-packages\jinja2\asyncsupport.py", line 76, in render
    return original_render(self, *args, **kwargs)
  File "C:\Users\Arina\Anaconda3\lib\site-packages\jinja2\environment.py", line 1008, in render
    return self.environment.handle_exception(exc_info, True)
  File "C:\Users\Arina\Anaconda3\lib\site-packages\jinja2\environment.py", line 780, in handle_exception
    reraise(exc_type, exc_value, tb)
  File "C:\Users\Arina\Anaconda3\lib\site-packages\jinja2\_compat.py", line 37, in reraise
    raise value.with_traceback(tb)
  File "C:\Users\Arina\python_git\Platform_for_sport\microblog\app\templates\profile.html", line 1, in top-level template code
    {% extends "base.html" %}
  File "C:\Users\Arina\python_git\Platform_for_sport\microblog\app\templates\base.html", line 37, in top-level template code
    {% block content %}{% endblock %}
  File "C:\Users\Arina\python_git\Platform_for_sport\microblog\app\templates\profile.html", line 46, in block "content"
    {% include '_post.html' %}
  File "C:\Users\Arina\python_git\Platform_for_sport\microblog\app\templates\_post.html", line 3, in top-level template code
    <td><img src="{{ e.author.avatar(36) }}"></td>
jinja2.exceptions.UndefinedError: 'dict object' has no attribute 'avatar'
2021-06-26 11:52:57,095 INFO: Microblog startup [in C:\Users\Arina\python_git\Platform_for_sport\microblog\app\__init__.py:45]
2021-06-26 11:56:55,319 INFO: Microblog startup [in C:\Users\Arina\python_git\Platform_for_sport\microblog\app\__init__.py:45]
2021-06-26 11:57:42,191 ERROR: Exception on /user/Arina [POST] [in C:\Users\Arina\Anaconda3\lib\site-packages\flask\app.py:1761]
Traceback (most recent call last):
  File "C:\Users\Arina\Anaconda3\lib\site-packages\flask\app.py", line 2292, in wsgi_app
    response = self.full_dispatch_request()
  File "C:\Users\Arina\Anaconda3\lib\site-packages\flask\app.py", line 1815, in full_dispatch_request
    rv = self.handle_user_exception(e)
  File "C:\Users\Arina\Anaconda3\lib\site-packages\flask\app.py", line 1718, in handle_user_exception
    reraise(exc_type, exc_value, tb)
  File "C:\Users\Arina\Anaconda3\lib\site-packages\flask\_compat.py", line 35, in reraise
    raise value
  File "C:\Users\Arina\Anaconda3\lib\site-packages\flask\app.py", line 1813, in full_dispatch_request
    rv = self.dispatch_request()
  File "C:\Users\Arina\Anaconda3\lib\site-packages\flask\app.py", line 1799, in dispatch_request
    return self.view_functions[rule.endpoint](**req.view_args)
  File "C:\Users\Arina\Anaconda3\lib\site-packages\flask_login\utils.py", line 272, in decorated_view
    return func(*args, **kwargs)
  File "C:\Users\Arina\python_git\Platform_for_sport\microblog\app\routes.py", line 64, in profile
    return redirect(url_for('profile'))
  File "C:\Users\Arina\Anaconda3\lib\site-packages\flask\helpers.py", line 356, in url_for
    return appctx.app.handle_url_build_error(error, endpoint, values)
  File "C:\Users\Arina\Anaconda3\lib\site-packages\flask\app.py", line 2061, in handle_url_build_error
    reraise(exc_type, exc_value, tb)
  File "C:\Users\Arina\Anaconda3\lib\site-packages\flask\_compat.py", line 35, in reraise
    raise value
  File "C:\Users\Arina\Anaconda3\lib\site-packages\flask\helpers.py", line 345, in url_for
    force_external=external)
  File "C:\Users\Arina\Anaconda3\lib\site-packages\werkzeug\routing.py", line 1776, in build
    raise BuildError(endpoint, values, method, self)
werkzeug.routing.BuildError: Could not build url for endpoint 'profile'. Did you forget to specify values ['username']?
2021-06-26 11:58:21,803 INFO: Microblog startup [in C:\Users\Arina\python_git\Platform_for_sport\microblog\app\__init__.py:45]
2021-06-26 11:59:50,456 INFO: Microblog startup [in C:\Users\Arina\python_git\Platform_for_sport\microblog\app\__init__.py:45]
2021-06-26 12:02:55,703 INFO: Microblog startup [in C:\Users\Arina\python_git\Platform_for_sport\microblog\app\__init__.py:45]
2021-06-26 12:06:00,707 INFO: Microblog startup [in C:\Users\Arina\python_git\Platform_for_sport\microblog\app\__init__.py:45]
2021-06-26 12:10:43,301 INFO: Microblog startup [in C:\Users\Arina\python_git\Platform_for_sport\microblog\app\__init__.py:45]
2021-06-26 15:32:25,039 INFO: Microblog startup [in C:\Users\Arina\python_git\Platform_for_sport\microblog\app\__init__.py:45]
2021-06-26 15:33:43,140 INFO: Microblog startup [in C:\Users\Arina\python_git\Platform_for_sport\microblog\app\__init__.py:45]
2021-06-26 15:35:38,770 INFO: Microblog startup [in C:\Users\Arina\python_git\Platform_for_sport\microblog\app\__init__.py:45]
2021-06-26 15:36:35,648 INFO: Microblog startup [in C:\Users\Arina\python_git\Platform_for_sport\microblog\app\__init__.py:45]
2021-06-26 15:38:42,011 INFO: Microblog startup [in C:\Users\Arina\python_git\Platform_for_sport\microblog\app\__init__.py:45]
2021-06-26 15:39:12,567 INFO: Microblog startup [in C:\Users\Arina\python_git\Platform_for_sport\microblog\app\__init__.py:45]
2021-06-26 15:39:16,810 ERROR: Exception on / [GET] [in C:\Users\Arina\Anaconda3\lib\site-packages\flask\app.py:1761]
Traceback (most recent call last):
  File "C:\Users\Arina\Anaconda3\lib\site-packages\flask\app.py", line 2292, in wsgi_app
    response = self.full_dispatch_request()
  File "C:\Users\Arina\Anaconda3\lib\site-packages\flask\app.py", line 1815, in full_dispatch_request
    rv = self.handle_user_exception(e)
  File "C:\Users\Arina\Anaconda3\lib\site-packages\flask\app.py", line 1718, in handle_user_exception
    reraise(exc_type, exc_value, tb)
  File "C:\Users\Arina\Anaconda3\lib\site-packages\flask\_compat.py", line 35, in reraise
    raise value
  File "C:\Users\Arina\Anaconda3\lib\site-packages\flask\app.py", line 1813, in full_dispatch_request
    rv = self.dispatch_request()
  File "C:\Users\Arina\Anaconda3\lib\site-packages\flask\app.py", line 1799, in dispatch_request
    return self.view_functions[rule.endpoint](**req.view_args)
  File "C:\Users\Arina\python_git\Platform_for_sport\microblog\app\routes.py", line 34, in general
    return render_template('general.html', title = 'Sport web-site')
  File "C:\Users\Arina\Anaconda3\lib\site-packages\flask\templating.py", line 135, in render_template
    context, ctx.app)
  File "C:\Users\Arina\Anaconda3\lib\site-packages\flask\templating.py", line 117, in _render
    rv = template.render(context)
  File "C:\Users\Arina\Anaconda3\lib\site-packages\jinja2\asyncsupport.py", line 76, in render
    return original_render(self, *args, **kwargs)
  File "C:\Users\Arina\Anaconda3\lib\site-packages\jinja2\environment.py", line 1008, in render
    return self.environment.handle_exception(exc_info, True)
  File "C:\Users\Arina\Anaconda3\lib\site-packages\jinja2\environment.py", line 780, in handle_exception
    reraise(exc_type, exc_value, tb)
  File "C:\Users\Arina\Anaconda3\lib\site-packages\jinja2\_compat.py", line 37, in reraise
    raise value.with_traceback(tb)
  File "C:\Users\Arina\python_git\Platform_for_sport\microblog\app\templates\general.html", line 1, in top-level template code
    {% extends "base.html" %}
  File "C:\Users\Arina\python_git\Platform_for_sport\microblog\app\templates\base.html", line 37, in top-level template code
    {% block content %}{% endblock %}
  File "C:\Users\Arina\python_git\Platform_for_sport\microblog\app\templates\general.html", line 6, in block "content"
    <h1>Hello, {{ user.username }}</h1>
  File "C:\Users\Arina\Anaconda3\lib\site-packages\jinja2\environment.py", line 430, in getattr
    return getattr(obj, attribute)
jinja2.exceptions.UndefinedError: 'user' is undefined
2021-06-26 15:47:58,261 INFO: Microblog startup [in C:\Users\Arina\python_git\Platform_for_sport\microblog\app\__init__.py:45]
2021-06-26 15:50:35,974 INFO: Microblog startup [in C:\Users\Arina\python_git\Platform_for_sport\microblog\app\__init__.py:45]
2021-06-26 15:55:50,022 INFO: Microblog startup [in C:\Users\Arina\python_git\Platform_for_sport\microblog\app\__init__.py:45]
2021-06-26 16:02:41,227 INFO: Microblog startup [in C:\Users\Arina\python_git\Platform_for_sport\microblog\app\__init__.py:45]
2021-06-26 16:04:58,266 INFO: Microblog startup [in C:\Users\Arina\python_git\Platform_for_sport\microblog\app\__init__.py:45]
2021-06-26 16:08:09,366 INFO: Microblog startup [in C:\Users\Arina\python_git\Platform_for_sport\microblog\app\__init__.py:45]
2021-06-26 16:19:55,071 INFO: Microblog startup [in C:\Users\Arina\python_git\Platform_for_sport\microblog\app\__init__.py:45]
